Workbook

Sheet 📊 TABLEAU DE BORD
B1: TABLEAU DE BORD GROUPAGE | 2019 – 2026
B4: Service NAT1 · Données opérationnelles & analytiques · Consolidé toutes années
B9: 💰 CHIFFRE D'AFFAIRES TOTAL | D9: ⚖️ POIDS TOTAL TRAITÉ | F9: 🤝 NOMBRE DE CLIENTS | H9: 🏆 MEILLEURE ANNÉE (CA) | J9: 🚢 NAVIRES UTILISÉS
B10: 0.61 Mrd FCFA | D10: 5,052 T | F10: 1,116 | H10: 2020 | J10: 62
B12: Sur 2019–2026 · 2,744 B/L traités | D12: Tonnes · Moyenne 1841 kg/BL | F12: Consignataires actifs · 1555 Shippers | H12: 107M FCFA | J12: Lignes maritimes différentes 2019-2026
B16: ▶ ÉVOLUTION ANNUELLE DES PERFORMANCES
B17: ANNÉE | C17: CA TOTAL (FCFA) | D17: NB BL | E17: POIDS (KG) | F17: VOLUME (M³) | G17: ÉVOL CA % | H17: CA MOY/BL | I17: PART POIDS
B18: 2019 | C18: 18726500 | D18: 109 | E18: 115737.93 | F18: 347.91 | G18: 0 | H18: 171802.75 | I18: 0.022911593
B19: 2020 | C19: 106717214 | D19: 582 | E19: 803850.64 | F19: 1721.191 | G19: 4.6987272 | H19: 183362.91 | I19: 0.15913106
B20: 2021 | C20: 93222260 | D20: 482 | E20: 622192.13 | F20: 4804.893 | G20: -0.12645527 | H20: 193407.18 | I20: 0.12316976
B21: 2022 | C21: 95324867 | D21: 456 | E21: 601911.44 | F21: 1567.2028 | G21: 0.022554777 | H21: 209045.76 | I21: 0.11915497
B22: 2023 | C22: 79843300 | D22: 368 | E22: 443636.26 | F22: 1129.2053 | G22: -0.16240848 | H22: 216965.49 | I22: 0.087822666
B23: 2024 | C23: 86303400 | D23: 328 | E23: 1240573.8 | F23: 1071.9569 | G23: 0.080909732 | H23: 263120.12 | I23: 0.2455852
B24: 2025 | C24: 67522812 | D24: 224 | E24: 947228.03 | F24: 737.188 | G24: -0.21761122 | H24: 301441.12 | I24: 0.18751418
B25: 2026 | C25: 58408012 | D25: 195 | E25: 276370.47 | F25: 666.15 | G25: -0.13498845 | H25: 299528.27 | I25: 0.054710568
B26: TOTAL | C26: 6.0606836e+08 | D26: 2744 | E26: 5051500.7 | F26: 12045.697 | I26: 100.0%
B29: ▶ TOP 15 CLIENTS (CONSIGNATAIRES) | G29: ▶ TOP 15 SHIPPERS (EXPÉDITEURS)
B30: CLIENT | C30: CA TOTAL | D30: NB B/L | E30: POIDS (KG) | F30: PART CA | G30: SHIPPER | H30: CA TOTAL | I30: NB B/L | J30: PART CA
B31: SNPT | C31: 94123280 | D31: 375 | E31: 678631.58 | F31: 0.48204241 | G31: DSV AIR & SEA CO LTD | H31: 6827300 | I31: 36 | J31: 0.11302163
B32: SCANTOGO MINES SA | C32: 22108040 | D32: 127 | E32: 156247.61 | F32: 0.11322399 | G32: FPS FAMOUS PACIFIC SHIPPING BV | H32: 5769420 | I32: 32 | J32: 0.095509098
B33: LCT | C33: 10229880 | D33: 38 | E33: 45646.85 | F33: 0.052391247 | G33: CABLES BARCIET | H33: 4747400 | I33: 4 | J33: 0.078590204
B34: CIMTOGO SA | C34: 9312400 | D34: 52 | E34: 55356 | F34: 0.04769247 | G34: CPS AFRICA | H34: 4710900 | I34: 18 | J34: 0.077985969
B35: REC LOGISTICS | C35: 8574460 | D35: 43 | E35: 64962.2 | F35: 0.043913189 | G35: DOUAISIS | H35: 4671160 | I35: 16 | J35: 0.077328099
B36: WACEM | C36: 7570580 | D36: 37 | E36: 29419.652 | F36: 0.038771924 | G36: AFCOCE | H36: 4454600 | I36: 1 | J36: 0.073743085
B37: DIAMOND CEMENT TOGO SA | C37: 6448345 | D37: 38 | E37: 33707.86 | F37: 0.033024516 | G37: STAN | H37: 4427380 | I37: 23 | J37: 0.073292475
B38: WEST AFRICAN CEMENT SA | C38: 6041589 | D38: 34 | E38: 39918.83 | F38: 0.030941358 | G38: FPS FAMOUS PACIFIC | H38: 4052260 | I38: 20 | J38: 0.067082601
B39: OMA LOGISTICS TOGO | C39: 5703940 | D39: 33 | E39: 28196.576 | F39: 0.029212125 | G39: DEGRILLON TECHNICAL | H39: 3460800 | I39: 18 | J39: 0.057291355
B40: BCEAO | C40: 4929660 | D40: 3 | E40: 1273 | F40: 0.025246732 | G40: MATAM SA NV | H40: 3094240 | I40: 16 | J40: 0.051223186
B41: RODIS LOME | C41: 4812260 | D41: 20 | E41: 48315.074 | F41: 0.02464548 | G41: DSV AIR & SEA PVT LTD | H41: 2961080 | I41: 13 | J41: 0.049018806
B42: AMERICAN AMBASSADOR | C42: 3985040 | D42: 18 | E42: 8743.893 | F42: 0.02040896 | G42: PORTUNUS PORT SPARES | H42: 2838700 | I42: 1 | J42: 0.046992883
... B45: N.P. GANDOUR | C45: 3678800 | D45: 15 | E45: 43837.035 | F45: 0.018840585 | G45: GEO SALES PRIVATE LTD | H45: 2774960 | I45: 17 | J45: 0.045937707

Sheet 📋 DONNÉES CONSOLIDÉES
A1: BASE DE DONNÉES GROUPAGE — NAT1 | 2019–2025 (source: feuille TOTAL)
A3: Total : 2549 enregistrements · Mis à jour automatiquement depuis la base brute
A5: N° | B5: NAVIRE | C5: N° B/L | D5: SHIPPER | E5: CONSIGNATAIRE | F5: QUANTITÉ | G5: POIDS (KG) | H5: VOL (M³) | I5: DOCS FEES (FCFA) | J5: MOIS | K5: ANNÉE
A6: 1 | B6: ATLANTIC | D6: A B COMEX SA | E6: NIOTO | F6: 2 | G6: 913.5 | H6: 0.754 | I6: 118260 | J6: JANVIER | K6: 2019
A7: 2 | B7: ATLANTIC | D7: ASSFOR LOGISTICS SA | E7: OMA LOGISTICS | F7: 6 | G7: 988 | H7: 4.784 | I7: 218000 | J7: JANVIER | K7: 2019
A8: 3 | B8: ATLANTIC | D8: POLYTRA NV | E8: LA BELGITUDE | F8: 4 | G8: 4315.2 | H8: 9.6 | I8: 358260 | J8: JANVIER | K8: 2019
A9: 4 | B9: ATLANTIC | D9: DHL GLOBAL | E9: SNPT | F9: 1 | G9: 986 | H9: 0.672 | I9: 118260 | J9: JANVIER | K9: 2019
A10: 5 | B10: ATLANTIC | D10: UNIPEX SOLUTIONS | E10: SIVOP TOGO | F10: 1 | G10: 650 | H10: 1.018 | I10: 118260 | J10: JANVIER | K10: 2019
A11: 6 | B11: ATLANTIC | D11: DSV AIR & SEA | E11: SCANTOGO MINES SA | F11: 4 | G11: 2520 | H11: 4.681 | I11: 228260 | J11: JANVIER | K11: 2019
A12: 7 | B12: ATLANTIC | D12: DHL GLOBAL | E12: ELECTROLUX US EMBASSY | F12: 2 | G12: 338 | H12: 4.388 | I12: 19000 | J12: JANVIER | K12: 2019
A13: 8 | B13: ATLANTIC | D13: ARGEVILLE | E13: SIVOP TOGO | F13: 1 | G13: 112.06 | H13: 0.912 | I13: 108000 | J13: JANVIER | K13: 2019
A14: 9 | B14: ATLANTIC | D14: INDO METAL | E14: WACEM SA | F14: 3 | G14: 415 | H14: 2.222 | I14: 134000 | J14: JANVIER | K14: 2019
A15: 10 | B15: ATLANTIC | D15: LARILYA SOLUTIONS | E15: ROTEC SAS | F15: 9 | G15: 1798 | H15: 11.285 | I15: 358260 | J15: JANVIER | K15: 2019
A16: 11 | B16: ATLANTIC | D16: BUISCAR CARGO SOLUTIONS | E16: LCT | F16: 4 | G16: 1589 | H16: 4.392 | I16: 200260 | J16: JANVIER | K16: 2019
A17: 12 | B17: ALABAMA | D17: MERK KGAA FRANKFURTER STRASE | E17: PEPINO SARL P/C FAO | F17: 2 | G17: 498.252 | H17: 1.728 | I17: 144260 | J17: JANVIER | K17: 2019
... A38: 33 | B38: MSC SHANNON | D38: DHL GLOBAL | E38: STE BABEL HA SARL | F38: 5 | G38: 3396 | H38: 5.523 | I38: 256260 | J38: FEVRIER | K38: 2019
A39: 34 | B39: MSC SHANNON | D39: DHL GLOBAL | E39: SNPT | F39: 1 | G39: 425.5 | H39: 0.816 | I39: 118260 | J39: FEVRIER | K39: 2019
A40: 35 | B40: MSC SHANNON | D40: JOBSON ITALIA SRL | E40: MSC TOGO SA | F40: 1 | G40: 135 | H40: 0.51 | I40: 108000 | J40: FEVRIER | K40: 2019
A41: 36 | B41: MSC SHANNON | D41: PRIME DISTRIBUTION SERVICES | E41: THE AFRICAN CONCEPT STORE | F41: 5 | G41: 3157.942 | H41: 8.684 | I41: 331260 | J41: FEVRIER | K41: 2019
A42: 37 | B42: MSC SHANNON | D42: VEPLUS RESOURCES SDN | E42: PROBIOMEPH SARL | F42: 2 | G42: 484 | H42: 1.83 | I42: 144260 | J42: FEVRIER | K42: 2019
A43: 38 | B43: MSC SHANNON | D43: CLEVE & ZONEN BV | E43: SIVOP TOGO | F43: 2 | G43: 340 | H43: 2.1 | I43: 134000 | J43: FEVRIER | K43: 2019
A44: 39 | B44: MSC SHANNON | D44: CD STAMPLEY ENTERPRISES | E44: EGLISE ADVENTISTE DU SEPTIEME JOUR | F44: 1 | G44: 514.833 | H44: 1.614 | I44: 144260 | J44: FEVRIER | K44: 2019
A45: 40 | B45: MSC GINA | D45: MATAM S A N V | E45: SNPT TOGO | F45: 3 | G45: 2847 | H45: 10.319 | I45: 358260 | J45: FEVRIER | K45: 2019
A46: 41 | B46: MSC GINA | D46: BEML LIMITED | E46: WACEM | F46: 8 | G46: 1459 | H46: 3.17 | I46: 162000 | J46: FEVRIER | K46: 2019
A47: 42 | B47: MSC GINA | D47: KONECRANES FINLANDOY | E47: LCT SA | F47: 1 | G47: 892 | H47: 1.382 | I47: 118260 | J47: FEVRIER | K47: 2019
A48: 43 | B48: MSC GINA | D48: DAIKIN MIDDLE EAST AND AFRICA FZE | E48: ARIC SA | F48: 3 | G48: 655.8 | H48: 4.44 | I48: 228260 | J48: FEVRIER | K48: 2019
A49: 44 | B49: MSC GINA | D49: IFS INTERNATIONAL FORWARDING | E49: ASSOCIATION BAPTISTS OF WORLD | F49: 2 | G49: 179 | H49: 1.568 | I49: 144260 | J49: FEVRIER | K49: 2019
A50: 45 | B50: MSC GINA | D50: IFS INTERNATIONAL FORWARDING | E50: SNPT TOGO | F50: 1 | G50: 185 | H50: 0.448 | I50: 118260 | J50: FEVRIER | K50: 2019
A51: 46 | B51: MSC GINA | D51: COMPAGNIE INTERNATIONALE DE MAINTENANCE | E51: SNPT TOGO | F51: 1 | G51: 36 | H51: 0.231 | I51: 118260 | J51: FEVRIER | K51: 2019
... A114: 109 | B114: MSC ALABAMA | D114: TEREX GLOBAL GMBH | E114: LCT | F114: 2 | G114: 1585 | H114: 2.704 | I114: 172260 | J114: MARS | K114: 2019
A115: 110 | B115: MSC INDIA | C115: ANR/LFW/06126 | D115: HEINEKEN BROUWERIJEN BV | E115: ETS HADDAD KHALIL | F115: 1 PALLET STC | G115: 90 | H115: 0.53 | I115: 108000 | J115: JANVIER | K115: 2020
A116: 111 | B116: MSC INDIA | C116: ANR/LFW/06127 | D116: HEINEKEN BROUWERIJEN BV | E116: RAMCO SA | F116: 1 PALLET | G116: 74 | H116: 0.6 | I116: 118260 | J116: JANVIER | K116: 2020
A117: 112 | B117: MSC INDIA | C117: ANR/LFW/06128 | D117: HEINEKEN BROUWERIJEN BV | E117: VASCO - MALI | F117: 1 PALLET | G117: 167 | H117: 0.84 | I117: 108000 | J117: JANVIER | K117: 2020
A118: 113 | B118: MSC INDIA | C118: ANR/LFW/06129 | D118: HEINEKEN BROUWERIJEN BV | E118: VASCO - BURKINA | F118: 3 PALLETS | G118: 654 | H118: 3.29 | I118: 162000 | J118: JANVIER | K118: 2020
A119: 114 | B119: MSC INDIA | C119: ANR/LFW/06131 | D119: CPS AFRICA | E119: CFAO MOTORS TOGO | F119: 3 PALLETS STC | G119: 620 | H119: 2.4 | I119: 144260 | J119: JANVIER | K119: 2020
A120: 115 | B120: MSC INDIA | C120: ANR/LFW/06132 | D120: DOUAISIS | E120: SNPT | F120: 7 CASES STC | G120: 7660 | H120: 12.62 | I120: 358260 | J120: JANVIER | K120: 2020
A121: 116 | B121: MSC INDIA | C121: ANR/LFW/06136 | D121: APPRO-TECHNO | E121: MINISTERE DES AFFAIRES ETRANGERES DE L'INTEGRATION | F121: 1 PALLET STC | G121: 600 | H121: 1.39 | I121: 118260 | J121: JANVIER | K121: 2020
A122: 117 | B122: MSC INDIA | C122: DKR/LFW/06134 | D122: ZENA EXOTICFUITS | E122: KALYAN HOSPITALITY DEVELOPMENT | F122: 1 COLIS STC | G122: 158 | H122: 1.2 | I122: 118260 | J122: JANVIER | K122: 2020
A123: 118 | B123: MSC INDIA | C123: JEA/LFW/00002 | D123: SYNERGY PROJECT MANAGEMENT | E123: ISLAMIC CENTRE FOR SOCIAL SERVICES AND EDUCATION | F123: 1 PALLET STC | G123: 572 | H123: 1.16 | I123: 118260 | J123: JANVIER | K123: 2020
A124: 119 | B124: MSC INDIA | C124: MIL/LFW/01524 | D124: MULTILOGISTICS SPA ON BEHALF OF | E124: TO MASTER OF SKS DARENT | F124: 6 CAGES STC | G124: 2010 | H124: 3.78 | I124: 190000 | J124: JANVIER | K124: 2020
...

Sheet 📅 ANALYSE MENSUELLE
B1: ANALYSE MENSUELLE DES REVENUS — PIVOT PAR ANNÉE
B3: Chiffre d'affaires (FCFA) — Groupage 2019–2025
B5: MOIS | C5: 2019 | D5: 2020 | E5: 2021 | F5: 2022 | G5: 2023 | H5: 2024 | I5: 2025 | J5: TOTAL | K5: MOIS MEILLEUR
B6: Jan | C6: 3739680 | D6: 8891580 | E6: 10988840 | F6: 7687580 | G6: 11838200 | H6: 5121000 | I6: 8106200 | J6: 56373080 | K6: 2023
B7: Fév | C7: 8640800 | D7: 4909460 | E7: 6428240 | F7: 8822567.3 | G7: 5264800 | H7: 4800800 | I7: 2900400 | J7: 41767067 | K7: 2022
B8: Mar | C8: 6346020 | D8: 10883400 | E8: 11119220 | F8: 8462060 | G8: 9174900 | H8: 11419000 | I8: 10368600 | J8: 67773200 | K8: 2024
B9: Avr | C9: 0 | D9: 10456920 | E9: 9492880 | F9: 7372760 | G9: 7375000 | H9: 9103000 | I9: 4551400 | J9: 48351960 | K9: 2020
B10: Mai | C10: 0 | D10: 9707840 | E10: 7869320 | F10: 4996700 | G10: 5019200 | H10: 5280600 | I10: 4551400 | J10: 37425060 | K10: 2020
B11: Jun | C11: 0 | D11: 7244580 | E11: 8850720 | F11: 12598000 | G11: 5125400 | H11: 4372600 | I11: 1865600 | J11: 40056900 | K11: 2022
B12: Jul | C12: 0 | D12: 10902920 | E12: 6661240 | F12: 5553200 | G12: 12287600 | H12: 8142600 | I12: 5544211.8 | J12: 49091772 | K12: 2023
B13: Aoû | C13: 0 | D13: 11976880 | E13: 13101560 | F13: 7451400 | G13: 5818400 | H13: 9775200 | I13: 8491600 | J13: 56615040 | K13: 2021
B14: Sep | C14: 0 | D14: 10560314 | E14: 7141280 | F14: 6885600 | G14: 4160200 | H14: 5427600 | I14: 7496600 | J14: 41671594 | K14: 2020
B15: Oct | C15: 0 | D15: 2882340 | E15: 4228680 | F15: 7430600 | G15: 2860400 | H15: 6427000 | I15: 5033600 | J15: 28862620 | K15: 2022
B16: Nov | C16: 0 | D16: 10059880 | E16: 4601420 | F16: 10614600 | G16: 3785200 | H16: 6670200 | I16: 6429200 | J16: 42160500 | K16: 2022
B17: Déc | C17: 0 | D17: 8241100 | E17: 2738860 | F17: 7449800 | G17: 7134000 | H17: 9763800 | I17: 2184000 | J17: 37511560 | K17: 2024
B18: TOTAL | C18: 18726500 | D18: 106717214 | E18: 93222260 | F18: 95324867 | G18: 79843300 | H18: 86303400 | I18: 67522812

Sheet 🚢 ANALYSE NAVIRES
B1: ANALYSE PAR NAVIRE — PERFORMANCE & ACTIVITÉ
B3: Top navires par nombre de B/L traités · 62 lignes au total
B5: NAVIRE | C5: NB B/L | D5: CA TOTAL (FCFA) | E5: POIDS TOTAL (KG) | F5: PART ACTIVITÉ
B6: MSC ORIANE | C6: 299 | D6: 63740580 | E6: 358819.65 | F6: 0.19814447
B7: MSC INDIA | C7: 294 | D7: 57673607 | E7: 724342.77 | F7: 0.19483101
B8: MSC KATYAYNI | C8: 182 | D8: 34556140 | E8: 200044.99 | F8: 0.12060968
B9: MSC MARTA | C9: 157 | D9: 37219632 | E9: 311964.08 | F9: 0.10404241
B10: MSC MARGARITA | C10: 111 | D10: 21959940 | E10: 140458.01 | F10: 0.073558648
B11: MSC DENMARK VI | C11: 109 | D11: 29207400 | E11: 797748.96 | F11: 0.072233267
B12: MSC KRYSTAL | C12: 98 | D12: 18088200 | E12: 127666.79 | F12: 0.064943671
B13: PORT GDYNIA | C13: 91 | D13: 18499200 | E13: 104215.22 | F13: 0.060304838
B14: GSL ALICE | C14: 89 | D14: 19383300 | E14: 105242.11 | F14: 0.058979457
B15: MSC CAROLINA | C15: 79 | D15: 16358700 | E15: 107626.28 | F15: 0.052352551

Sheet 📈 HISTORIQUE CLIENTS
A1: HISTORIQUE ANNUEL — ÉVOLUTION CA PAR CLIENT CIBLE
A3: CA (FCFA) et nombre de BL par année · Clients sélectionnés pour prospection
A5: CLIENT | B5: 2019 | D5: 2020 | F5: 2021 | H5: 2022 | J5: 2023 | L5: 2024 | N5: 2025
A6: CLIENT | B6: CA (FCFA) | C6: NB BL | D6: CA (FCFA) | E6: NB BL | F6: CA (FCFA) | G6: NB BL | H6: CA (FCFA) | I6: NB BL | J6: CA (FCFA) | K6: NB BL | L6: CA (FCFA) | M6: NB BL | N6: CA (FCFA) | O6: NB BL
A7: SCANTOGO MINES SA | B7: 693040 | C7: 4 | D7: 6574140 | E7: 40 | F7: 3969980 | G7: 23 | H7: 5084080 | I7: 28 | J7: 3949400 | K7: 24 | L7: 1581600 | M7: 7 | N7: 255800 | O7: 1
A8: REC LOGISTICS | D8: 2888640 | E8: 14 | F8: 5185500 | G8: 26 | H8: 500320 | I8: 3
A9: CIMTOGO SA | D9: 1952120 | E9: 12 | F9: 2356900 | G9: 15 | H9: 2737780 | I9: 13 | J9: 1748200 | K9: 9 | L9: 517400 | M9: 3
A10: DIAMOND CEMENT TOGO SA | D10: 1895925 | E10: 10 | F10: 2999600 | G10: 19 | H10: 1552820 | I10: 9
A11: WEST AFRICAN CEMENT SA | D11: 3221069 | E11: 19 | F11: 1926260 | G11: 11 | H11: 894260 | I11: 4
A12: OMA LOGISTICS TOGO | D12: 601780 | E12: 4 | F12: 5102160 | G12: 29
A13: INTER-SEAS TOGO | D13: 2153820 | E13: 13 | F13: 437780 | G13: 3 | H13: 1354460 | I13: 5
A14: AMERICAN AMBASSADOR | D14: 1397000 | E14: 6 | F14: 1984780 | G14: 10 | H14: 247260 | I14: 1 | N14: 356000 | O14: 1
A15: REC LOGISTIC | D15: 1574080 | E15: 8 | H15: 1951680 | I15: 10
A16: TAAL SA | D16: 1052780 | E16: 6 | F16: 1719040 | G16: 8 | H16: 326520 | I16: 2
A17: SMT TOGO SARL | D17: 1422820 | E17: 7 | F17: 631780 | G17: 3 | H17: 801580 | I17: 4 | J17: 227800 | K17: 1
A18: SIVOP TOGO | B18: 190000 | C18: 1 | D18: 2181000 | E18: 14 | H18: 464000 | I18: 2 | J18: 169000 | K18: 1
A19: BOLLORE TRANSPORT & LOGISTICS TOGO | D19: 709780 | E19: 4 | F19: 1793080 | G19: 8
A20: TOTAL TOGO | D20: 1023300 | E20: 5 | F20: 1226300 | G20: 5 | J20: 358800 | K20: 1
A21: CAMEG TOGO | D21: 826040 | E21: 4 | F21: 823040 | G21: 4 | H21: 317600 | I21: 2 | L21: 530600 | M21: 2

Sheet 📈 2026 (MARGES)
A1: DONNÉES 2026 — ANALYSE AVEC MARGE DE FACTURATION
A4: CA TOTAL 2026 | D4: MARGE TOTALE | G4: NB B/L 2026 | J4: TAUX DE MARGE MOY
A5: 58.4M FCFA | D5: 3.74M FCFA | G5: 195 | J5: 39.8%
A8: N° | B8: NAVIRE | C8: N° B/L | D8: SHIPPER | E8: CONSIGNATAIRE | F8: QUANTITÉ | G8: POIDS (KG) | H8: VOL (M³) | I8: DOCS FEES | J8: MONTANT NORMAL | K8: MARGE | L8: TAUX MARGE
A9: 1 | B9: MSC IKARIA VI | C9: KEL/LFW/08826 | D9: MING WEI PAPERWARE | E9: IMEP SARL | F9: 3 WOODEN CASES | G9: 130 | H9: 0.51 | I9: 227800 | J9: 145800 | K9: 82000 | L9: 0.56241427
A10: 2 | B10: MSC IKARIA VI | C10: LON/LFW/00427 | D10: WHO | E10: PORT OF ENTRY LOME | F10: 3 PALLETS STC | G10: 279 | H10: 4.57 | I10: 331800 | J10: 255800 | K10: 76000 | L10: 0.29710711
A11: 3 | B11: MSC IKARIA VI | C11: MIL/LFW/08822 | D11: BASF ITALIA SPA | E11: RODIS TOGO | F11: 3 PALLETS STC | G11: 2626.8 | H11: 4.563 | I11: 358800 | J11: 255800 | K11: 103000 | L11: 0.40265833
A12: 4 | B12: MSC IKARIA VI | C12: MIL/LFW/08834 | D12: FIOCCHETTI SCIENTIFIC SRL | E12: BGL SYSMET TOGO | F12: 5 CRATES STC | G12: 1170 | H12: 8.056 | I12: 385800 | J12: 331800 | K12: 54000 | L12: 0.16274864
A13: 5 | B13: MSC IKARIA VI | C13: MIL/LFW/08843 | D13: WESTERN CO.SRL | E13: ESCAN GLOBAL TOGO | F13: 1 PALLET STC | G13: 210 | H13: 0.624 | I13: 253000 | J13: 24200 | K13: 11000 | L13: 0.45454545
A14: 6 | B14: MSC IKARIA VI | C14: SHA/LFW/08825 | D14: SUNWARD INTELLIGENT | E14: SUNWARD TOGO | F14: 1 CASE STC | G14: 876 | H14: 2.4 | I14: 329000 | J14: 169000 | K14: 160000 | L14: 0.94674556
A15: 7 | B15: MSC BENIN | C15: ANR/LFW/08873 | D15: DHL LOGISTICS | E15: NP GANDOUR SARL | F15: 6 PALLETS STC | G15: 4594.8 | H15: 7.997 | I15: 408000 | J15: 331800 | K15: 76200 | L15: 0.22965642
A16: 8 | B16: MSC BENIN | C16: ANR/LFW/08889 | D16: SMT AFRICA NV/SA | E16: SMT TOGO SARL | F16: 9 PACKAGES STC | G16: 3090 | H16: 8.57 | I16: 385800 | J16: 358800 | K16: 27000 | L16: 0.075250836
A17: 9 | B17: MSC BENIN | C17: LON/LFW/00432 | D17: DURBIN PLC | E17: HOSPITAL OF HOPE | F17: 3 PACKAGES STC | G17: 499 | H17: 4.527 | I17: 356800 | J17: 255800 | K17: 101000 | L17: 0.39483972
A18: 10 | B18: MSC BENIN | C18: LYS/LFW/08870 | D18: MLT MINET LACING | E18: SNPT | F18: 1 PALLET STC | G18: 538 | H18: 1.286 | I18: 308800 | J18: 145800 | K18: 163000 | L18: 1.1179698
A19: 11 | B19: MSC BENIN | C19: LYS/LFW/08879 | D19: MLT MINET LACING | E19: WACEM TOGO | F19: 1 PALLET STC | G19: 358 | H19: 1.363 | I19: 306000 | J19: 143000 | K19: 163000 | L19: 1.1398601
A20: 12 | B20: MSC BENIN | C20: MIL/LFW/08858 | D20: FIOCCHETTI SCIENTIFIC SRL | E20: BGL SYSMET TOGO | F20: 8 CASES STC | G20: 1635.8 | H20: 9.023 | I20: 385800 | J20: 358800 | K20: 27000 | L20: 0.075250836
... A51: 43 | B51: MSC IKARIA | C51: RTM/LFW/08912 | D51: VAN VLIET | E51: VAN VLIET TOGO | F51: 3 PALLETS | G51: 626.5 | H51: 5.004 | I51: 358800 | J51: 280800 | K51: 78000 | L51: 0.27777778
A52: 44 | B52: MSC ORIANE | C52: ANR/LFW/08503 | D52: COMPAGNIE ENGRENAGES | E52: SNPT | F52: 1 CASE STC | G52: 1015 | H52: 2.44 | I52: 331800 | J52: 171800 | K52: =I52-J52 -> 160000 | L52: 0
A53: 45 | B53: MSC ORIANE | C53: ANR/LFW/08507 | D53: XINDA GROUP | E53: SNPT | F53: 1 CASE STC | G53: 195.5 | H53: 1.152 | I53: 143000 | J53: 143000 | K53: =I53-J53 -> 0 | L53: 0
A54: 46 | B54: MSC ORIANE | C54: ANR/LFW/08508 | D54: KUEHME + NAGEL | E54: SNPT | F54: 1 CASE STC | G54: 199 | H54: 0.698 | I54: 145800 | J54: 145800 | K54: =I54-J54 -> 0 | L54: 0
A55: 47 | B55: MSC ORIANE | C55: BRS/LFW/08489 | D55: CEVA AIR & OCEAN | E55: CEVA LOGISTICS | F55: 1 PALLET STC | G55: 410 | H55: 0.346 | I55: 225000 | J55: 145800 | K55: =I55-J55 -> 79200 | L55: 0
A56: 48 | B56: MSC ORIANE | C56: HKG/LFW/00320 | D56: SHENZHEN HENGTAI | E56: ASECNA | F56: 7 PACKAGES STC | G56: 5659 | H56: 4.74 | I56: 283800 | J56: 283800 | K56: 0 | L56: 0
A57: 49 | B57: MSC ORIANE | C57: KHH/LFW/2501209 | D57: CHAO WEI PLASTIC | E57: SOCIPLAST | F57: 1 WOODEN CRATE | G57: 1302 | H57: 1.6 | I57: 309000 | L57: 0
A58: 50 | B58: MSC ORIANE | C58: LEH/LFW/08492 | D58: TLD SPR | E58: ST HANDLING | F58: 1 PALLET STC | G58: 557 | H58: 0.998 | I58: 171800 | L58: 0
A59: 51 | B59: MSC ORIANE | C59: LEH/LFW/08495 | D59: TENTEKS TENTE BRANDA | E59: LOME TENLEKS | F59: 3 PACAKAGES STC | G59: 1891.8 | H59: 10.08 | I59: 385800 | L59: 0
A60: 52 | B60: MSC ORIANE | C60: LEH/LFW/08500 | D60: TLD SPR | E60: SNPT | F60: 1 CASE STC | G60: 229 | H60: 1.746 | I60: 171800 | L60: 0
A61: 53 | B61: MSC ORIANE | C61: MIL/LFW/08506 | D61: PARFER SITTI | E61: CIM METAL | F61: 3 PALLETS STC | G61: 1360 | H61: 1.824 | I61: 169000 | L61: 0
A62: 54 | B62: MSC ORIANE | C62: TXG/LFW/2501208 | D62: JIN YU SING ENTERPRISE | E62: PLASTICA TOGO | F62: 1 WOODEN CRATE | G62: 164 | H62: 0.54 | I62: 143000 | L62: 0
A63: 55 | B63: MSC JOHNNESBURG | C63: ANR/LFW/08496 | D63: ATLAS COPCO | E63: PREMIUM TOGO | F63: 1 CASE STC | G63: 3612 | H63: 12.916 | I63: 385800 | L63: 0
A64: 56 | B64: MSC JOHNNESBURG | C64: ANR/LFW/08517 | D64: ELSO AMERICAN EMBASSY | E64: AMERICAN EMBASSY | F64: 1 CASE STC | G64: 731 | H64: 5.641 | I64: 281000 | L64: 0
A65: 57 | B65: MSC JOHNNESBURG | C65: ANR/LFW/08527 | D65: KUEHME + NAGEL | E65: CIMTOGO | F65: 1 PALLET STC | G65: 125 | H65: 0.264 | I65: 145800 | L65: 0
A66: 58 | B66: MSC JOHNNESBURG | C66: ANR/LFW/08528 | D66: SILESIA GERHANKE | E66: UNIFOOD TOGO | F66: 1 PALLET STC | G66: 623.9 | H66: 1.344 | I66: 143000 | L66: 0
A67: 59 | B67: MSC JOHNNESBURG | C67: ANR/LFW/08529 | D67: FRACHT AG | E67: CME TECTOOLS | F67: 1 PALLET STC | G67: 365 | H67: 5.44 | I67: 253000 | L67: 0
A68: 60 | B68: MSC JOHNNESBURG | C68: ANR/LFW/08530 | D68: GURTEC GMBH | E68: SNPT | F68: 1 PALLET STC | G68: 1135 | H68: 0.768 | I68: 331800 | L68: 0
... A121: 113 | B121: MSC SORAYA | C121: ANR/LFW/08658 | D121: CEVA AIR & OCEAN | E121: CEVA LOGISTICS TOGO | F121: 4 PALLETS STC | G121: 2636 | H121: 4.812 | I121: 253000 | L121: 0
A122: 114 | B122: MSC SORAYA | C122: ANR/LFW/08661 | E122: SNPT | F122: 1 CASE STC | G122: 322 | H122: 0.913 | I122: 255800 | L122: 0
A123: 115 | B123: MSC SORAYA | C123: ANR/LFW/08662 | D123: MA CORPORATION PTE | E123: MSC TOGO | F123: 1 PACAKAGES STC | G123: 4100 | H123: 1.896 | I123: 329000 | L123: 0
A124: 116 | B124: MSC SORAYA | C124: ANR/LFW/08642 | D124: ASECNA PARIS | E124: ESECNA TOGO | F124: 1 CASE STC | G124: 660 | H124: 1.617 | I124: 171800 | L124: 0
A125: 117 | B125: MSC SORAYA | C125: LEH/LFW/08651 | D125: FICHET SECURITY SOLUTIONS | E125: ACOPRESS | F125: 2 CASES STC | G125: 1582 | H125: 2.562 | I125: 199800 | L125: 0
A126: 118 | B126: MSC SORAYA | C126: LEH/LFW/08654 | D126: SOSEA | E126: NSCT | F126: 8 PALLETS STC | G126: 717 | H126: 2.301 | I126: 171800 | L126: 0
...

Sheet 🚚 SHIPPERS À RELANCER
A1: SHIPPERS À RELANCER — EXPÉDITEURS CLÉS DISPARUS OU EN DÉCLIN
A3: Relancer un shipper = récupérer automatiquement ses consignataires associés
A5: SHIPPER / EXPÉDITEUR | B5: CA PASSÉ (FCFA) | C5: CA ACTUEL (FCFA) | D5: BAISSE (FCFA) | E5: BAISSE % | F5: NB BL PASSÉ | G5: NB BL ACTUEL | H5: STATUT
A6: FPS FAMOUS PACIFIC SHIPPING BV | B6: 5769420 | C6: 0 | D6: 5769420 | E6: 1 | F6: 32 | G6: 0 | H6: PERDU
A7: DSV AIR & SEA CO LTD | B7: 5179300 | C7: 1648000 | D7: 3531300 | E7: 0.68181028 | F7: 26 | G7: 10 | H7: EN DÉCLIN
A8: DOUAISIS | B8: 4671160 | C8: 0 | D8: 4671160 | E8: 1 | F8: 16 | G8: 0 | H8: PERDU
A9: FPS FAMOUS PACIFIC | B9: 3709460 | C9: 342800 | D9: 3366660 | E9: 0.90758763 | F9: 18 | G9: 2 | H9: EN DÉCLIN
A10: CPS AFRICA | B10: 3304500 | C10: 1406400 | D10: 1898100 | E10: 0.57439855 | F10: 10 | G10: 8 | H10: EN DÉCLIN
A11: DEGRILLON TECHNICAL SUPPLIES | B11: 2824160 | C11: 0 | D11: 2824160 | E11: 1 | F11: 17 | G11: 0 | H11: PERDU
A12: DSV AIR & SEA PVT LTD | B12: 2649280 | C12: 311800 | D12: 2337480 | E12: 0.88230765 | F12: 12 | G12: 1 | H12: EN DÉCLIN
A13: MATAM SA NV | B13: 2610640 | C13: 483600 | D13: 2127040 | E13: 0.81475807 | F13: 14 | G13: 2 | H13: EN DÉCLIN
A14: DTS DEGRILLON TECHNICAL SUPPLIES | B14: 2346160 | C14: 0 | D14: 2346160 | E14: 1 | F14: 16 | G14: 0 | H14: PERDU
A15: GEO SALES PRIVATE LTD | B15: 2314360 | C15: 460600 | D15: 1853760 | E15: 0.8009817 | F15: 14 | G15: 3 | H15: EN DÉCLIN
A16: VANGUARD LOGISTICS SERVICES | B16: 2264340 | C16: 0 | D16: 2264340 | E16: 1 | F16: 14 | G16: 0 | H16: PERDU
A17: CLEVE & ZONEN BV | B17: 2136100 | C17: 0 | D17: 2136100 | E17: 1 | F17: 12 | G17: 0 | H17: PERDU
... A20: VANGUARD LOGISTICS | B20: 1976260 | C20: 816400 | D20: 1159860 | E20: 0.58689646 | F20: 8 | G20: 4 | H20: EN DÉCLIN

Sheet 👥 SYNTHÈSE CLIENTS
A1: ANALYSE COMPLÈTE DES CLIENTS — CLASSEMENT & FIDÉLITÉ
A3: 1116 clients uniques identifiés sur la période 2019–2025
A5: CLIENT / CONSIGNATAIRE | B5: CA TOTAL | C5: NB B/L | D5: ANNÉES ACTIF | E5: POIDS TOTAL | F5: PART CA | G5: CA MOY/BL
A6: SNPT | B6: 94123280 | C6: 375 | D6: 7 | E6: 678631.58 | F6: 0.17186433 | G6: 250995.41
A7: SCANTOGO MINES SA | B7: 22108040 | C7: 127 | D7: 7 | E7: 156247.61 | F7: 0.040368159 | G7: 174079.06
A8: LCT | B8: 10229880 | C8: 38 | D8: 6 | E8: 45646.85 | F8: 0.018679242 | G8: 269207.37
A9: CIMTOGO SA | B9: 9312400 | C9: 52 | D9: 5 | E9: 55356 | F9: 0.01700397 | G9: 179084.62
A10: REC LOGISTICS | B10: 8574460 | C10: 43 | D10: 3 | E10: 64962.2 | F10: 0.015656529 | G10: 199406.05
A11: WACEM | B11: 7570580 | C11: 37 | D11: 5 | E11: 29419.652 | F11: 0.013823495 | G11: 204610.27
A12: DIAMOND CEMENT TOGO SA | B12: 6448345 | C12: 38 | D12: 3 | E12: 33707.86 | F12: 0.011774351 | G12: 169693.29
A13: WEST AFRICAN CEMENT SA | B13: 6041589 | C13: 34 | D13: 3 | E13: 39918.83 | F13: 0.011031635 | G13: 177693.79
A14: OMA LOGISTICS TOGO | B14: 5703940 | C14: 33 | D14: 2 | E14: 28196.576 | F14: 0.010415105 | G14: 172846.67
A15: BCEAO | B15: 4929660 | C15: 3 | D15: 3 | E15: 1273 | F15: 0.0090013089 | G15: 1643220
A16: RODIS LOME | B16: 4812260 | C16: 20 | D16: 4 | E16: 48315.074 | F16: 0.0087869424 | G16: 240613
A17: AMERICAN AMBASSADOR | B17: 3985040 | C17: 18 | D17: 4 | E17: 8743.893 | F17: 0.0072764807 | G17: 221391.11
... A1121: HI SPEED | B1121: 247.26 | C1121: 1 | D1121: 1 | E1121: 1248 | F1121: 4.5148421e-07 | G1121: 247.26

Sheet 🎯 SYNTHÈSE PROSPECTS
B1: PLAN DE PROSPECTION COMMERCIALE — GROUPAGE NAT1
B4: Top 15 clients à reconquérir · Analyse basée sur données 2019–2025 · Classé par potentiel CA
B8: CA POTENTIEL À RÉCUPÉRER | D8: CLIENTS TOTALEMENT PERDUS | F8: CLIENTS EN FORT DÉCLIN | H8: PRIORITÉ N°1
B9: 0.07 Mrd FCFA | D9: 8 comptes | F9: 7 comptes | H9: SCANTOGO MINES SA…
B15: ▶ TOP 15 CLIENTS À PROSPECTER EN PRIORITÉ
A16: Num D'ordre | B16: CLIENT / CONSIGNATAIRE | C16: CA PASSÉ (FCFA) | D16: CA ACTUEL (FCFA) | E16: BAISSE (FCFA) | F16: BAISSE % | G16: ANS ACTIF | H16: DERNIER BL | I16: STATUT | J16: ACTION RECOMMANDÉE
A17: 1 | B17: SCANTOGO MINES SA | C17: 16321240 | D17: 5786800 | E17: 10534440 | F17: 0.64544361 | G17: 4 | H17: 2022 | I17: EN DÉCLIN | J17: Réunion commerciale — proposer offre personnalisée
A18: 2 | B18: REC LOGISTICS | C18: 8574460 | D18: 0 | E18: 8574460 | F18: 1 | G18: 3 | H18: 2022 | I18: PERDU | J18: Appel de reconquête — identifier motif départ
A19: 3 | B19: CIMTOGO SA | C19: 7046800 | D19: 2265600 | E19: 4781200 | F19: 0.67849237 | G19: 3 | H19: 2022 | I19: EN DÉCLIN | J19: Réunion commerciale — proposer offre personnalisée
A20: 4 | B20: DIAMOND CEMENT TOGO SA | C20: 6448345 | D20: 0 | E20: 6448345 | F20: 1 | G20: 3 | H20: 2022 | I20: PERDU | J20: Appel de reconquête — identifier motif départ
A21: 5 | B21: WEST AFRICAN CEMENT SA | C21: 6041589 | D21: 0 | E21: 6041589 | F21: 1 | G21: 3 | H21: 2022 | I21: PERDU | J21: Appel de reconquête — identifier motif départ
A22: 6 | B22: OMA LOGISTICS TOGO | C22: 5703940 | D22: 0 | E22: 5703940 | F22: 1 | G22: 2 | H22: 2021 | I22: PERDU | J22: Appel de reconquête — identifier motif départ
A23: 7 | B23: INTER-SEAS TOGO | C23: 3946060 | D23: 0 | E23: 3946060 | F23: 1 | G23: 3 | H23: 2022 | I23: PERDU | J23: Appel de reconquête — identifier motif départ
A24: 8 | B24: AMERICAN AMBASSADOR | C24: 3629040 | D24: 356000 | E24: 3273040 | F24: 0.90190243 | G24: 3 | H24: 2022 | I24: EN DÉCLIN | J24: Réunion commerciale — proposer offre personnalisée
A25: 9 | B25: REC LOGISTIC | C25: 3525760 | D25: 0 | E25: 3525760 | F25: 1 | G25: 2 | H25: 2022 | I25: PERDU | J25: Appel de reconquête — identifier motif départ
A26: 10 | B26: TAAL SA | C26: 3098340 | D26: 0 | E26: 3098340 | F26: 1 | G26: 3 | H26: 2022 | I26: PERDU | J26: Appel de reconquête — identifier motif départ
A27: 11 | B27: SMT TOGO SARL | C27: 2856180 | D27: 227800 | E27: 2628380 | F27: 0.92024312 | G27: 3 | H27: 2022 | I27: EN DÉCLIN | J27: Réunion commerciale — proposer offre personnalisée
A28: 12 | B28: SIVOP TOGO | C28: 2835000 | D28: 169000 | E28: 2666000 | F28: 0.94038801 | G28: 3 | H28: 2022 | I28: EN DÉCLIN | J28: Réunion commerciale — proposer offre personnalisée
... A31: 15 | B31: CAMEG TOGO | C31: 1966680 | D31: 530600 | E31: 1436080 | F31: 0.73020522 | G31: 3 | H31: 2022 | I31: EN DÉCLIN | J31: Réunion commerciale — proposer offre personnalisée

Sheet 💼 Opportunités
A1: SUIVI DES OPPORTUNITÉS COMMERCIALES
A4: Service Commercial & LCL · Cotations Import / Export · TAAL SA
A8: TOTAL COTATIONS | C8: OFFRES GAGNÉES | E8: OFFRES PERDUES | G8: MARGE TOTALE (EUR)
A9: =COUNTA(C16:C1032) -> 16 | C9: =COUNTIF(H16:H1032,"GAGNÉ") -> 3 | E9: =COUNTIF(H16:H1032,"PERDU") -> 4 | G9: =IFERROR(SUM(G16:G1032),0) -> 8256.526
A15: N° COTATION | B15: DATE | C15: NOM CLIENT | D15: TYPE SERVICE | E15: OFFRE TRANSITAIRE (FCFA) | F15: COTATION CLIENT (FCFA) | G15: MARGE TAAL SA (FCFA) | H15: RÉSULTAT | I15: OBSERVATIONS
A16: =IF(C16="","",TEXT(1,"COT-000")) -> COT-001 | B16: 46032 | C16: SCANTOGO MINES | D16: IMPORT | E16: 442 | F16: 771.83 | G16: =IF(OR(E16="",F16=""),"",F16-E16) -> 329.83 | H16: GAGNÉ | I16: FRET AERIEN
A17: =IF(C17="","",TEXT(2,"COT-000")) -> COT-002 | B17: 46034 | C17: SNPT | D17: IMPORT | E17: 631.5 | F17: 1360 | G17: =IF(OR(E17="",F17=""),"",F17-E17) -> 728.5 | H17: GAGNÉ | I17: FRET MARITIME
A18: =IF(C18="","",TEXT(3,"COT-000")) -> COT-003 | B18: 46055 | C18: SCANTOGO MINES | D18: IMPORT | E18: 735.9 | F18: 1143.55 | G18: =IF(OR(E18="",F18=""),"",F18-E18) -> 407.65 | H18: PERDU | I18: FRET MARITIME
A19: =IF(C19="","",TEXT(4,"COT-000")) -> COT-004 | B19: 46058 | C19: ABM SERVICES | D19: IMPORT | E19: 670.48 | F19: 1113.626 | G19: =IF(OR(E19="",F19=""),"",F19-E19) -> 443.146 | H19: PERDU | I19: FRET MARITIME
A20: =IF(C20="","",TEXT(5,"COT-000")) -> COT-005 | B20: 46065 | C20: ECU WORLDWIDE USA | D20: IMPORT | E20: 4348.83 | F20: 5432 | G20: =IF(OR(E20="",F20=""),"",F20-E20) -> 1083.17 | H20: PERDU | I20: FRET MARITIME
A21: =IF(C21="","",TEXT(6,"COT-000")) -> COT-006 | B21: 46062 | C21: ECU WORLDWIDE TUNISIE | D21: IMPORT | E21: 867.66 | F21: 1353.5 | G21: =IF(OR(E21="",F21=""),"",F21-E21) -> 485.84 | H21: EN COURS | I21: FRET MARITIME
A22: =IF(C22="","",TEXT(7,"COT-000")) -> COT-007 | B22: 46056 | C22: ECU WORLDWIDE Espagne | D22: IMPORT | E22: 941.33 | F22: 1126.43 | G22: =IF(OR(E22="",F22=""),"",F22-E22) -> 185.1 | H22: EN COURS | I22: FRET MARITIME
A23: =IF(C23="","",TEXT(8,"COT-000")) -> COT-008 | B23: 46084 | C23: ELWA GHANA | D23: EXPORT | E23: 1876.65 | F23: 3176.65 | G23: =IF(OR(E23="",F23=""),"",F23-E23) -> 1300 | H23: EN COURS | I23: FRET MARITIME
A24: =IF(C24="","",TEXT(9,"COT-000")) -> COT-009 | B24: 46084 | C24: ELWA GHANA | D24: EXPORT | E24: 695.5 | F24: 1345 | G24: =IF(OR(E24="",F24=""),"",F24-E24) -> 649.5 | H24: PERDU | I24: FRET MARITIME
A25: =IF(C25="","",TEXT(10,"COT-000")) -> COT-010 | B25: 46090 | C25: MASTER MV TASMANIA | D25: IMPORT | E25: 197.65 | F25: 377.33 | G25: =IF(OR(E25="",F25=""),"",F25-E25) -> 179.68 | H25: EN COURS | I25: FRET AERIEN
A26: =IF(C26="","",TEXT(11,"COT-000")) -> COT-011 | B26: 46112 | C26: FRATELLI COSULICH | D26: IMPORT | E26: 3128.84 | F26: 3985.88 | G26: =IF(OR(E26="",F26=""),"",F26-E26) -> 857.04 | H26: EN COURS | I26: FRET AERIEN
A27: =IF(C27="","",TEXT(12,"COT-000")) -> COT-012 | B27: 46112 | C27: ELWA GHANA | D27: EXPORT | E27: 646.74 | F27: 1394.32 | G27: =IF(OR(E27="",F27=""),"",F27-E27) -> 747.58 | H27: EN COURS | I27: FRET EXPORT
A28: =IF(C28="","",TEXT(13,"COT-000")) -> COT-013 | B28: 46121 | C28: MARCO PATILI | D28: IMPORT | E28: 1913.17 | F28: 2213.17 | G28: =IF(OR(E28="",F28=""),"",F28-E28) -> 300 | H28: ANNULÉ | I28: TRANSIT 01*40
A29: =IF(C29="","",TEXT(14,"COT-000")) -> COT-014 | B29: 46115 | C29: RECA TOGO SARL | D29: IMPORT | E29: 125.46 | F29: 136.24 | G29: =IF(OR(E29="",F29=""),"",F29-E29) -> 10.78 | H29: EN COURS | I29: COT 2000 TONNES DE RIZ / TONNE
A30: =IF(C30="","",TEXT(15,"COT-000")) -> COT-015 | B30: 46125 | C30: LINT CLEANER TURKYE | D30: EXPORT | E30: 1905.61 | F30: 2334.31 | G30: =IF(OR(E30="",F30=""),"",F30-E30) -> 428.7 | H30: GAGNÉ | I30: COT EXPORT 25 TC 20'' COTONOU - TURQUIE
A31: =IF(C31="","",TEXT(16,"COT-000")) -> COT-016 | B31: 46127 | C31: UNDP TOGO | D31: IMPORT | E31: 993.81 | F31: 1113.82 | G31: =IF(OR(E31="",F31=""),"",F31-E31) -> 120.01 | H31: EN COURS | I31: FORMALITES DE TRANSIT LOME PORT A MAISON
A64: =IF(C64="","",TEXT(17,"COT-000")) | G64: =IF(OR(E64="",F64=""),"",F64-E64)
A65: =IF(C65="","",TEXT(18,"COT-000")) | G65: =IF(OR(E65="",F65=""),"",F65-E65)
A66: =IF(C66="","",TEXT(19,"COT-000")) | G66: =IF(OR(E66="",F66=""),"",F66-E66)
A67: =IF(C67="","",TEXT(20,"COT-000")) | G67: =IF(OR(E67="",F67=""),"",F67-E67)
A68: =IF(C68="","",TEXT(21,"COT-000")) | G68: =IF(OR(E68="",F68=""),"",F68-E68)
A69: =IF(C69="","",TEXT(22,"COT-000")) | G69: =IF(OR(E69="",F69=""),"",F69-E69)
A70: =IF(C70="","",TEXT(23,"COT-000")) | G70: =IF(OR(E70="",F70=""),"",F70-E70)
A71: =IF(C71="","",TEXT(24,"COT-000")) | G71: =IF(OR(E71="",F71=""),"",F71-E71)
A72: =IF(C72="","",TEXT(25,"COT-000")) | G72: =IF(OR(E72="",F72=""),"",F72-E72)
A73: =IF(C73="","",TEXT(26,"COT-000")) | G73: =IF(OR(E73="",F73=""),"",F73-E73)
A74: =IF(C74="","",TEXT(27,"COT-000")) | G74: =IF(OR(E74="",F74=""),"",F74-E74)
A75: =IF(C75="","",TEXT(28,"COT-000")) | G75: =IF(OR(E75="",F75=""),"",F75-E75)
A76: =IF(C76="","",TEXT(29,"COT-000")) | G76: =IF(OR(E76="",F76=""),"",F76-E76)
A77: =IF(C77="","",TEXT(30,"COT-000")) | G77: =IF(OR(E77="",F77=""),"",F77-E77)
A78: =IF(C78="","",TEXT(31,"COT-000")) | G78: =IF(OR(E78="",F78=""),"",F78-E78)
A79: =IF(C79="","",TEXT(32,"COT-000")) | G79: =IF(OR(E79="",F79=""),"",F79-E79)
A80: =IF(C80="","",TEXT(33,"COT-000")) | G80: =IF(OR(E80="",F80=""),"",F80-E80)
A81: =IF(C81="","",TEXT(34,"COT-000")) | G81: =IF(OR(E81="",F81=""),"",F81-E81)
A82: =IF(C82="","",TEXT(35,"COT-000")) | G82: =IF(OR(E82="",F82=""),"",F82-E82)
...

Sheet 📊 Récapitulatif Commercial
A1: RÉCAPITULATIF — SERVICE COMMERCIAL & LCL
A4: Synthèse automatique liée à l'onglet Opportunités · Tableau de bord de performance
B8: TOTAL COTATIONS | E8: OFFRES GAGNÉES | H8: OFFRES PERDUES | K8: MARGE TOTALE (FCFA)
B9: ='💼 Opportunités'!A9 -> 16 | E9: ='💼 Opportunités'!C9 -> 3 | H9: ='💼 Opportunités'!E9 -> 4 | K9: ='💼 Opportunités'!G9 -> 8256.526
B14: TAUX DE RÉUSSITE : | F14: =IFERROR(C9/B9,0) -> 0 | H14: MARGE MOYENNE / COTATION : | L14: =IFERROR(D9/B9,0) -> 0
B16: ▶ A — RÉPARTITION PAR TYPE DE SERVICE (Automatique)
B17: TYPE | C17: NB COTATIONS | D17: GAGNÉES | E17: PERDUES | F17: EN COURS | G17: ANNULÉES | H17: CA GAGNÉ (FCFA) | I17: MARGE (FCFA) | J17: TAUX RÉUSSITE
B18: IMPORT | C18: =COUNTIF('💼 Opportunités'!D16:D147,"IMPORT") -> 12 | D18: =COUNTIFS('💼 Opportunités'!D16:D147,"IMPORT",'💼 Opportunités'!H16:H147,"GAGNÉ") -> 2 | E18: =COUNTIFS('💼 Opportunités'!D16:D147,"IMPORT",'💼 Opportunités'!H16:H147,"PERDU") -> 3 | F18: =COUNTIFS('💼 Opportunités'!D16:D147,"IMPORT",'💼 Opportunités'!H16:H147,"EN COURS") -> 6 | G18: =COUNTIFS('💼 Opportunités'!D16:D147,"IMPORT",'💼 Opportunités'!H16:H147,"ANNULÉ") -> 1 | H18: =SUMIFS('💼 Opportunités'!F16:F147,'💼 Opportunités'!D16:D147,"IMPORT",'💼 Opportunités'!H16:H147,"GAGNÉ") -> 2131.83 | I18: =SUMIFS('💼 Opportunités'!G16:G147,'💼 Opportunités'!D16:D147,"IMPORT",'💼 Opportunités'!H16:H147,"GAGNÉ") -> 1058.33 | J18: =IFERROR(D18/C18,0) -> 0.16666667
B19: EXPORT | C19: =COUNTIF('💼 Opportunités'!D16:D147,"EXPORT") -> 4 | D19: =COUNTIFS('💼 Opportunités'!D16:D147,"EXPORT",'💼 Opportunités'!H16:H147,"GAGNÉ") -> 1 | E19: =COUNTIFS('💼 Opportunités'!D16:D147,"EXPORT",'💼 Opportunités'!H16:H147,"PERDU") -> 1 | F19: =COUNTIFS('💼 Opportunités'!D16:D147,"EXPORT",'💼 Opportunités'!H16:H147,"EN COURS") -> 2 | G19: =COUNTIFS('💼 Opportunités'!D16:D147,"EXPORT",'💼 Opportunités'!H16:H147,"ANNULÉ") -> 0 | H19: =SUMIFS('💼 Opportunités'!F16:F147,'💼 Opportunités'!D16:D147,"EXPORT",'💼 Opportunités'!H16:H147,"GAGNÉ") -> 2334.31 | I19: =SUMIFS('💼 Opportunités'!G16:G147,'💼 Opportunités'!D16:D147,"EXPORT",'💼 Opportunités'!H16:H147,"GAGNÉ") -> 428.7 | J19: =IFERROR(D19/C19,0) -> 0.25
B20: TOTAL | C20: =SUM(C18:C19) -> 16 | D20: =SUM(D18:D19) -> 3 | E20: =SUM(E18:E19) -> 4 | F20: =SUM(F18:F19) -> 8 | G20: =SUM(G18:G19) -> 1 | H20: =SUM(H18:H19) -> 4466.14 | I20: =SUM(I18:I19) -> 1487.03 | J20: =IFERROR(D20/C20,0) -> 0.1875
B22: ▶ B — SUIVI MENSUEL DE PERFORMANCE (Saisie manuelle par le service)
B23: INDICATEUR | C23: JAN | D23: FÉV | E23: MAR | F23: AVR | G23: MAI | H23: JUN | I23: JUL | J23: AOÛT | K23: SEP | L23: OCT | M23: NOV | N23: DÉC
B24: Nb cotations émises
B25: Nb offres gagnées
B26: Nb offres perdues
B27: CA gagné (FCFA)
B28: Marge réalisée (FCFA)
B29: Taux de réussite (%)
B30: TOTAL ANNUEL | C30: =SUM(C24:C26) -> 0 | D30: =SUM(D24:D26) -> 0 | E30: =SUM(E24:E26) -> 0 | F30: =SUM(F24:F26) -> 0 | G30: =SUM(G24:G26) -> 0 | H30: =SUM(H24:H26) -> 0 | I30: =SUM(I24:I26) -> 0 | J30: =SUM(J24:J26) -> 0 | ... N30: =SUM(N24:N26) -> 0
B32: ▶ C — PARAMÈTRES & OBJECTIFS COMMERCIAUX
B33: Objectif cotations / mois
B34: Objectif taux de réussite (%)
B35: Objectif marge mensuelle (FCFA)
B36: Responsable commercial
B37: Responsable LCL
B38: Période de référence
